<?xml version="1.0" ?>
<!-- =================================================================================== -->
<!-- |    This document was autogenerated by xacro from kak.urdf.xacro                 | -->
<!-- |    EDITING THIS FILE BY HAND IS NOT RECOMMENDED                                 | -->
<!-- =================================================================================== -->
<robot name="kak">
  <gazebo>
    <!--plugin
            filename="gz-sim-pose-publisher-system"
            name="gz::sim::systems::PosePublisher">
            <publish_link_pose>true</publish_link_pose>
            <use_pose_vector_msg>true</use_pose_vector_msg>
            <static_publisher>true</static_publisher>
            <static_update_frequency>1</static_update_frequency>
        </plugin-->
    <!--plugin
            filename="gz-sim-odometry-publisher-system"
            name="gz::sim::systems::OdometryPublisher">
            <odom_frame>kak/odom</odom_frame>
            <robot_base_frame>kak/base_link</robot_base_frame>
            <odom_publish_frequency>50</odom_publish_frequency>
        </plugin-->
    <plugin filename="gz-sim-joint-state-publisher-system" name="gz::sim::systems::JointStatePublisher">
        </plugin>
    <plugin filename="gz-sim-diff-drive-system" name="gz::sim::systems::DiffDrive">
      <left_joint>wheel_1_joint</left_joint>
      <right_joint>wheel_2_joint</right_joint>
      <child_frame_id>kak/base_link</child_frame_id>
      <wheel_separation>0.35</wheel_separation>
      <wheel_radius>0.1</wheel_radius>
      <odom_publish_frequency>10</odom_publish_frequency>
    </plugin>
  </gazebo>
  <material name="Gray">
    <color rgba="0.2 0.2 0.2 1.0"/>
  </material>
  <material name="Pink">
    <color rgba="0.84 0.4 0.3 0.9"/>
  </material>
  <material name="Brown">
    <color rgba="0.5 0.2 0.1 1.0"/>
  </material>
  <material name="Green">
    <color rgba="0.112 0.21 0.021 1.0"/>
  </material>
  <material name="White">
    <color rgba="1 1 1 1.0"/>
  </material>
  <material name="Blue">
    <color rgba="0 0 0.2 1.0"/>
  </material>
  <!--Base link-->
  <link name="base_link">
    <origin rpy="0 0 0" xyz="0 1 0"/>
  </link>
  <!-- Robot Footprint -->
  <link name="base_footprint"/>
  <joint name="base_joint" type="fixed">
    <parent link="base_link"/>
    <child link="base_footprint"/>
    <origin rpy="0 0 0" xyz="0.0 0.0 0.0"/>
  </joint>
  <link name="stol">
    <visual>
      <origin rpy="0 0 0" xyz="0 0 -0.38"/>
      <geometry>
        <cylinder length="0.07" radius="1.0"/>
      </geometry>
      <material name="Gray"/>
    </visual>
    <collision>
      <geometry>
        <cylinder length="0.07" radius="1.0"/>
      </geometry>
    </collision>
    <inertial>
      <origin rpy="1.5707963267948966 0 0" xyz="0 0 0"/>
      <mass value="0.5"/>
      <inertia ixx="0.12520416666666667" ixy="0" ixz="0" iyy="0.12520416666666667" iyz="0" izz="0.25"/>
    </inertial>
  </link>
  <joint name="stol_joint" type="fixed">
    <parent link="base_link"/>
    <child link="stol"/>
    <origin rpy="0 0 0" xyz="0.0 0.0 0.0"/>
  </joint>
  <!-- * * * Link Definitions * * * -->
  <link name="vaza">
    <visual>
      <geometry>
        <box size="0.52 0.56 0.685"/>
      </geometry>
      <material name="Pink"/>
    </visual>
    <collision>
      <geometry>
        <box size="0.52 0.56 0.685"/>
      </geometry>
    </collision>
    <inertial>
      <origin rpy="1.5707963267948966 0 1.5707963267948966" xyz="0 0 0"/>
      <mass value="15"/>
      <inertia ixx="0.9785312500000001" ixy="0.0" ixz="0.0" iyy="0.7300000000000001" iyz="0.0" izz="0.9245312500000001"/>
    </inertial>
  </link>
  <joint name="vaza_joint" type="fixed">
    <parent link="stol"/>
    <child link="vaza"/>
    <origin rpy="0 0 0" xyz="0 0 0"/>
  </joint>
  <link name="zemlya">
    <visual>
      <geometry>
        <box size="0.42 0.46 0.585"/>
      </geometry>
      <material name="Brown"/>
    </visual>
    <collision>
      <geometry>
        <box size="0.42 0.46 0.585"/>
      </geometry>
    </collision>
    <inertial>
      <origin rpy="1.5707963267948966 0 1.5707963267948966" xyz="0 0 0"/>
      <mass value="15"/>
      <inertia ixx="0.69228125" ixy="0.0" ixz="0.0" iyy="0.485" iyz="0.0" izz="0.6482812499999999"/>
    </inertial>
  </link>
  <joint name="zemlya_joint" type="fixed">
    <parent link="stol"/>
    <child link="zemlya"/>
    <origin rpy="0 0 0" xyz="0 0 0.1"/>
  </joint>
  <link name="kaktys">
    <visual>
      <geometry>
        <cylinder length="1.7" radius="0.15"/>
      </geometry>
      <material name="Green"/>
    </visual>
    <collision>
      <geometry>
        <cylinder length="1.7" radius="0.15"/>
      </geometry>
    </collision>
    <inertial>
      <origin rpy="1.5707963267948966 0 0" xyz="0 0 0"/>
      <mass value="1"/>
      <inertia ixx="0.24645833333333328" ixy="0" ixz="0" iyy="0.24645833333333328" iyz="0" izz="0.01125"/>
    </inertial>
  </link>
  <joint name="kaktys_joint" type="fixed">
    <parent link="stol"/>
    <child link="kaktys"/>
    <origin rpy="0 0 0" xyz="0 0 0.5"/>
  </joint>
  <link name="vetka_1">
    <visual>
      <geometry>
        <cylinder length="1.0" radius="0.1"/>
      </geometry>
      <material name="Green"/>
    </visual>
    <collision>
      <geometry>
        <cylinder length="1.0" radius="0.1"/>
      </geometry>
    </collision>
    <inertial>
      <origin rpy="1.5707963267948966 0 0" xyz="0 0 0"/>
      <mass value="0.7"/>
      <inertia ixx="0.06008333333333333" ixy="0" ixz="0" iyy="0.06008333333333333" iyz="0" izz="0.0035000000000000005"/>
    </inertial>
  </link>
  <joint name="vetka_1_joint" type="fixed">
    <parent link="kaktys"/>
    <child link="vetka_1"/>
    <origin rpy="90 0 0" xyz="0 0 0.5"/>
  </joint>
  <link name="vetka_2">
    <visual>
      <geometry>
        <cylinder length="0.6" radius="0.08"/>
      </geometry>
      <material name="Green"/>
    </visual>
    <collision>
      <geometry>
        <cylinder length="0.6" radius="0.08"/>
      </geometry>
    </collision>
    <inertial>
      <origin rpy="1.5707963267948966 0 0" xyz="0 0 0"/>
      <mass value="0.2"/>
      <inertia ixx="0.006319999999999999" ixy="0" ixz="0" iyy="0.006319999999999999" iyz="0" izz="0.00064"/>
    </inertial>
  </link>
  <joint name="vetka_2_joint" type="fixed">
    <parent link="kaktys"/>
    <child link="vetka_2"/>
    <origin rpy="0 0 0" xyz="0 -0.4 0.6"/>
  </joint>
  <link name="igla_1">
    <visual>
      <geometry>
        <box size="0.05 0.45 0.05"/>
      </geometry>
      <material name="White"/>
    </visual>
    <collision>
      <geometry>
        <box size="0.05 0.45 0.05"/>
      </geometry>
    </collision>
    <inertial>
      <origin rpy="1.5707963267948966 0 1.5707963267948966" xyz="0 0 0"/>
      <mass value="0.1"/>
      <inertia ixx="0.0017083333333333334" ixy="0.0" ixz="0.0" iyy="0.0017083333333333334" iyz="0.0" izz="4.166666666666667e-05"/>
    </inertial>
  </link>
  <joint name="igla_1_joint" type="fixed">
    <parent link="kaktys"/>
    <child link="igla_1"/>
    <origin rpy="0 0 0" xyz="0 0 0.1225"/>
  </joint>
  <link name="igla_2">
    <visual>
      <geometry>
        <box size="0.45 0.05 0.05"/>
      </geometry>
      <material name="White"/>
    </visual>
    <collision>
      <geometry>
        <box size="0.45 0.05 0.05"/>
      </geometry>
    </collision>
    <inertial>
      <origin rpy="1.5707963267948966 0 1.5707963267948966" xyz="0 0 0"/>
      <mass value="0.1"/>
      <inertia ixx="4.166666666666667e-05" ixy="0.0" ixz="0.0" iyy="0.0017083333333333334" iyz="0.0" izz="0.0017083333333333334"/>
    </inertial>
  </link>
  <joint name="igla_2_joint" type="fixed">
    <parent link="kaktys"/>
    <child link="igla_2"/>
    <origin rpy="0 0 0" xyz="0 0 0.1225"/>
  </joint>
  <link name="igla_3">
    <visual>
      <geometry>
        <box size="0.45 0.05 0.05"/>
      </geometry>
      <material name="White"/>
    </visual>
    <collision>
      <geometry>
        <box size="0.45 0.05 0.05"/>
      </geometry>
    </collision>
    <inertial>
      <origin rpy="1.5707963267948966 0 1.5707963267948966" xyz="0 0 0"/>
      <mass value="0.1"/>
      <inertia ixx="4.166666666666667e-05" ixy="0.0" ixz="0.0" iyy="0.0017083333333333334" iyz="0.0" izz="0.0017083333333333334"/>
    </inertial>
  </link>
  <joint name="igla_3_joint" type="fixed">
    <parent link="kaktys"/>
    <child link="igla_3"/>
    <origin rpy="0 0 0" xyz="0 0 0.3225"/>
  </joint>
  <link name="igla_4">
    <visual>
      <geometry>
        <box size="0.45 0.05 0.05"/>
      </geometry>
      <material name="White"/>
    </visual>
    <collision>
      <geometry>
        <box size="0.45 0.05 0.05"/>
      </geometry>
    </collision>
    <inertial>
      <origin rpy="1.5707963267948966 0 1.5707963267948966" xyz="0 0 0"/>
      <mass value="0.1"/>
      <inertia ixx="4.166666666666667e-05" ixy="0.0" ixz="0.0" iyy="0.0017083333333333334" iyz="0.0" izz="0.0017083333333333334"/>
    </inertial>
  </link>
  <joint name="igla_4_joint" type="fixed">
    <parent link="kaktys"/>
    <child link="igla_4"/>
    <origin rpy="0 0 0" xyz="0 0 0.5225"/>
  </joint>
  <link name="igla_5">
    <visual>
      <geometry>
        <box size="0.05 0.45 0.05"/>
      </geometry>
      <material name="White"/>
    </visual>
    <collision>
      <geometry>
        <box size="0.05 0.45 0.05"/>
      </geometry>
    </collision>
    <inertial>
      <origin rpy="1.5707963267948966 0 1.5707963267948966" xyz="0 0 0"/>
      <mass value="0.1"/>
      <inertia ixx="0.0017083333333333334" ixy="0.0" ixz="0.0" iyy="0.0017083333333333334" iyz="0.0" izz="4.166666666666667e-05"/>
    </inertial>
  </link>
  <joint name="igla_5_joint" type="fixed">
    <parent link="kaktys"/>
    <child link="igla_5"/>
    <origin rpy="0 0 0" xyz="0 0 0.7225"/>
  </joint>
  <link name="igla_6">
    <visual>
      <geometry>
        <box size="0.45 0.05 0.05"/>
      </geometry>
      <material name="White"/>
    </visual>
    <collision>
      <geometry>
        <box size="0.45 0.05 0.05"/>
      </geometry>
    </collision>
    <inertial>
      <origin rpy="1.5707963267948966 0 1.5707963267948966" xyz="0 0 0"/>
      <mass value="0.1"/>
      <inertia ixx="4.166666666666667e-05" ixy="0.0" ixz="0.0" iyy="0.0017083333333333334" iyz="0.0" izz="0.0017083333333333334"/>
    </inertial>
  </link>
  <joint name="igla_6_joint" type="fixed">
    <parent link="kaktys"/>
    <child link="igla_6"/>
    <origin rpy="0 0 0" xyz="0 0 0.7225"/>
  </joint>
  <link name="wheel_1">
    <visual>
      <origin rpy="1.56 0 0" xyz="0 0 0"/>
      <geometry>
        <cylinder length="0.15" radius="0.35"/>
      </geometry>
      <material name="Blue"/>
    </visual>
    <collision>
      <origin rpy="1.5707963267948966 0 0" xyz="0 0 0"/>
      <geometry>
        <cylinder length="0.15" radius="0.35"/>
      </geometry>
    </collision>
    <inertial>
      <origin rpy="1.5707963267948966 0 0" xyz="0 0 0"/>
      <mass value="0.7"/>
      <inertia ixx="0.022749999999999996" ixy="0" ixz="0" iyy="0.022749999999999996" iyz="0" izz="0.04287499999999999"/>
    </inertial>
  </link>
  <joint name="wheel_1_joint" type="continuous">
    <parent link="stol"/>
    <child link="wheel_1"/>
    <origin rpy="0 0 1.56" xyz="0.9 -0.5 -0.45"/>
    <axis xyz="0 1 0"/>
  </joint>
  <link name="wheel_2">
    <visual>
      <origin rpy="1.56 0 0" xyz="0 0 0"/>
      <geometry>
        <cylinder length="0.15" radius="0.35"/>
      </geometry>
      <material name="Blue"/>
    </visual>
    <collision>
      <origin rpy="1.5707963267948966 0 0" xyz="0 0 0"/>
      <geometry>
        <cylinder length="0.15" radius="0.35"/>
      </geometry>
    </collision>
    <inertial>
      <origin rpy="1.5707963267948966 0 0" xyz="0 0 0"/>
      <mass value="0.7"/>
      <inertia ixx="0.022749999999999996" ixy="0" ixz="0" iyy="0.022749999999999996" iyz="0" izz="0.04287499999999999"/>
    </inertial>
  </link>
  <joint name="wheel_2_joint" type="continuous">
    <parent link="stol"/>
    <child link="wheel_2"/>
    <origin rpy="0 0 1.56" xyz="-0.9 -0.5 -0.45"/>
    <axis xyz="0 1 0"/>
  </joint>
  <link name="weel_center">
    <visual>
      <geometry>
        <sphere radius="0.2"/>
      </geometry>
      <material name="Blue"/>
    </visual>
    <collision>
      <geometry>
        <sphere radius="0.2"/>
      </geometry>
    </collision>
    <inertial>
      <mass value="0.1"/>
      <inertia ixx="0.0016000000000000007" ixy="0.0" ixz="0.0" iyy="0.0016000000000000007" iyz="0.0" izz="0.0016000000000000007"/>
    </inertial>
  </link>
  <joint name="weel_center_joint" type="continuous">
    <parent link="stol"/>
    <child link="weel_center"/>
    <origin rpy="0 1.56 0" xyz="0 0.6 -0.6"/>
  </joint>
</robot>
